<mujoco model="2dof_arm">
  <compiler angle="degree"/>
  <option timestep="0.002" gravity="0 0 -9.81" integrator="RK4" iterations="50"/>
  <asset>
    <texture name="skybox" type="skybox" builtin="flat" rgb1="1 1 1" rgb2="0 0 0" width="512" height="512"/>
    <texture name="grid" type="2d" builtin="checker" rgb1=".15 .2 .25" rgb2=".25 .3 .35" width="300" height="300" mark="edge" markrgb=".3 .4 .5"/>
    <material name="grid_mat" texture="grid" texrepeat="2 2" texuniform="true" reflectance="0.2"/>
    
    <material name="black_metal" rgba="0.15 0.18 0.2 1" specular="0.8" shininess="0.7" reflectance="0.5"/>
    <material name="blue_metal" rgba="0.2 0.4 0.6 1" specular="0.9" shininess="0.8" reflectance="0.6"/>
    <material name="dark_grey" rgba="0.25 0.28 0.3 1" specular="0.7" shininess="0.6" reflectance="0.4"/>
    <material name="silver_metal" rgba="0.7 0.75 0.8 1" specular="0.95" shininess="0.9" reflectance="0.75"/>
    <material name="steel_grey" rgba="0.5 0.55 0.6 1" specular="0.85" shininess="0.75" reflectance="0.6"/>
  </asset>
  
  <worldbody>
    <light mode="fixed" pos="0 0 3" dir="0 0 -1" directional="true" diffuse="1 1 1" specular="0.5 0.5 0.5"/>
    <light pos="2 2 2" dir="-0.5 -0.5 -1" directional="true" diffuse="0.4 0.4 0.4"/>
    
    <geom name="floor" type="plane" size="2 2 0.02" material="grid_mat"/>
    <body name="box" pos="0 0.5 0">
      <geom name="box" type="box" size="0.03 0.03 0.03"/>
    </body>
    <body name="platform" pos="0 0 0">
      <geom name="platform_base" type="cylinder" size="0.15 0.03" material="dark_grey"/>
      <geom name="platform_rim" type="cylinder" size="0.16 0.02" pos="0 0 0.05" material="black_metal"/>
    </body>
    
    <body name="base" pos="0 0 0.06">
      <!-- <joint name="base" type="fixed"/> -->
      <geom name="base_column" type="cylinder" size="0.08 0.1" pos="0 0 0.1" material="black_metal"/>
      <geom name="base_housing" type="cylinder" size="0.09 0.04" pos="0 0 0.2" material="black_metal"/>
    </body>
    
    <body name="link1" pos="0 0 0.3">
      <joint name="shoulder_yaw" type="hinge" axis="0 0 1" range="-180 180" damping="5"/>
      <joint name="shoulder_pitch" type="hinge" axis="0 1 0" range="-90 90" damping="5"/>
      <inertial pos="0.225 0 0" mass="2.5" diaginertia="0.15 0.15 0.15"/>
      
      <geom name="shoulder_joint" type="sphere" size="0.04" material="blue_metal"/>
      <geom name="capsule" type="capsule" fromto="0 0 0.04 0 0 0.4" size="0.04" material="black_metal"/>
      
      <body name="link2" pos="0 0 0.4">
        <joint name="shoulder_yaw2" type="hinge" axis="0 0 1" range="-180 180" damping="5"/>
        <joint name="shoulder_pitch2" type="hinge" axis="0 1 0" range="-120 120" damping="5"/>
        <inertial pos="0.175 0 0" mass="1.8" diaginertia="0.08 0.08 0.08"/>
        
        <geom name="shoulder_joint2" type="sphere" size="0.04" material="blue_metal"/>
        <geom name="capsule2" type="capsule" fromto="0 0 0.03 0 0 0.5" size="0.04" material="steel_grey"/>
        
        <body name="hand" pos="0 0 0.54">
          <geom type="box" size="0.03 0.09 0.04" material="black_metal"/>
          
          <body name="right_gripper" pos="0 0.07 0.05">
            <joint name="right" type="slide" axis="0 1 0" range="0 0.06"/>
            <geom type="box" size="0.015 0.01 0.05" material="black_metal"/>
          </body>
          
          <body name="left_gripper" pos="0 -0.07 0.05">
            <joint name="left" type="slide" axis="0 -1 0" range="0 0.06"/>
            <geom type="box" size="0.015 0.01 0.05" material="black_metal"/>
          </body>
        </body>
      </body>
    </body>
  </worldbody>
  
  <equality>
    <joint joint1="right" joint2="left"/>
  </equality>
  
  <tendon>
    <fixed name="grasp">
      <joint joint="right" coef="1"/>
      <joint joint="left" coef="1"/>
    </fixed>
  </tendon>
  
  <actuator>
    <motor name="shoulder_yaw" joint="shoulder_yaw" gear="50"/>
    <motor name="shoulder_pitch" joint="shoulder_pitch" gear="50"/>
    <motor name="shoulder_yaw2" joint="shoulder_yaw2" gear="50"/>
    <motor name="shoulder_pitch2" joint="shoulder_pitch2" gear="50"/>
    <position name="grasp" tendon="grasp" kp="200" ctrlrange="-1 0"/>
  </actuator>
</mujoco>